Workbook

Sheet invoice_test_data
A1: IVCE_DTL_UID | B1: IVCE_HDR_ID | C1: CMPY_DVSN_NUM | D1: IVCE_NUM | E1: Vender Lookup | F1: VNDR_ID | G1: IVCE_LNE_NUM | H1: ITM_LDSC | I1: ITM_QTY | J1: ITM_UOM_CD | K1: ITM_PRC_CD | L1: ITM_UNT_CST_AMT | M1: MFR_NM | N1: MFR_PRT_NUM | O1: VNDR_PRT_NUM | P1: AKS_PRT_NUM | Q1: UPC_CD | R1: XTNDD_CST_AMT | S1: REC_UPDD_DTTM | T1: REC_UPDD_BY_ID | U1: REC_CRTD_DTTM | V1: REC_CRTD_BY_ID | W1: PRCH_ORDR_DTL_UID | X1: PRCH_ORDR_LNE_NUM | Y1: LNE_ITM_STAT_CD | Z1: CVRTD_CTRT_PRC_AMT | AA1: CVRTD_PRCH_ORDR_PRC_AMT | AB1: CTRT_ID | AC1: CLN_MFR_NM | AD1: CLN_MFR_AI_NM | AE1: IVCE_LNE_STAT | AF1: UNSPSC_CD | AG1: WEBSITE Link | AH1: AI Consideration? | AI1: CLASSIFICATION | AJ1: CLASSIFICATION | AK1: Notes | AL1: ItemID | AM1: MfrPartNum | AN1: MfrName | AO1: UPC | AP1: UNSPSC | AQ1: AKPartNum | AR1: DescriptionID | AS1: ItemDescription | AT1: CleanName | AU1: UncleanName | AV1: MfrNameMatchType | AW1: DescriptionSimilarity | AX1: PartNumberConfidenceScore | AY1: ManufacturerNameConfidenceScore | AZ1: UNSPSCConfidenceScore | BA1: Semantic_MfrName | BB1: Semantic_MfrNameConfidenceScore | BC1: Semantic_UNSPSC | BD1: Semantic_UNSPSCConfidenceScore | BE1: Semantic_IsMfrClean
A2: 905679 | B2: 281619 | C2: NULL | D2: 6082907-0018 | F2: 14555 | G2: 1 | H2: YALE GP050VX 5,000# WAREHOUSE FORKLIFT | I2: 1 | J2: E | K2: E | L2: 975 | M2: YALE | N2: GP050VX | O2: NULL | P2: NULL | Q2: NULL | R2: 975 | S2: 45744.48 | T2: PA_SRDC | U2: 45744.264 | V2: PAUSER | W2: NULL | X2: 0 | Y2: 999 | Z2: NULL | AA2: NULL | AB2: NULL | AC2: RENTAL - UNDEFINED | AD2: RENTAL - UNDEFINED | AE2: AI | AF2: - | AG2: https://www.crescorent.com/equipment-rentals/5000-warehouse-forklift/ | AI2: MATERIAL | AJ2: =VLOOKUP(A2,'Classification Test Result'!$A$2:$D$2428,4,FALSE) -> #N/A | AL2: =_xlfn.XLOOKUP($A2,Results!$A$2:$A$2256,Results!G$2:G$2256,"") -> 0 | AM2: =_xlfn.XLOOKUP($A2,Results!$A$2:$A$2256,Results!H$2:H$2256,"") -> 0 | AN2: =_xlfn.XLOOKUP($A2,Results!$A$2:$A$2256,Results!I$2:I$2256,"") -> 0 | AO2: =_xlfn.XLOOKUP($A2,Results!$A$2:$A$2256,Results!J$2:J$2256,"") -> 0 | AP2: =_xlfn.XLOOKUP($A2,Results!$A$2:$A$2256,Results!K$2:K$2256,"") -> 0 | AQ2: =_xlfn.XLOOKUP($A2,Results!$A$2:$A$2256,Results!L$2:L$2256,"") -> 0 | AR2: =_xlfn.XLOOKUP($A2,Results!$A$2:$A$2256,Results!M$2:M$2256,"") -> 0 | AS2: =_xlfn.XLOOKUP($A2,Results!$A$2:$A$2256,Results!N$2:N$2256,"") -> 0 | ... BE2: =_xlfn.XLOOKUP($A2,Results!$A$2:$A$2256,Results!Z$2:Z$2256,"") -> 0
A3: 905680 | B3: 281389 | C3: NULL | D3: 9341431319 | E3: =VLOOKUP(F3,'RPA Vendor Data '!F1:$G$2418,2) -> GRAYBAR ELECTRIC CO. INC. | F3: 11471 | G3: 2 | H3: X7 COOPER CROUSE-HINDS DIVISION CHICO CHICO X FIBER 1 LB AK10289128 | I3: 1 | J3: 1 | K3: E | L3: 117.85 | M3: CROUSE-HINDS | N3: CHICO X7 | O3: NULL | P3: AK10289128 | Q3: NULL | R3: 117.85 | S3: 45744.272 | T3: PA_SRDC | U3: 45744.053 | V3: PAUSER | W3: NULL | X3: 2 | Y3: 201,0,0 | Z3: NULL | AA3: 117.85 | AB3: NULL | AC3: EATON DISTRIBUTION EQUIP | AD3: EATON DISTRIBUTION EQUIP | AE3: AI | AF3: 39121337 | AG3: https://www.graybar.com/chico174-x-fiber-1-lb-box/p/88069549 | AI3: MATERIAL | AJ3: =VLOOKUP(A3,'Classification Test Result'!$A$2:$D$2428,4,FALSE) -> #N/A | AL3: =_xlfn.XLOOKUP($A3,Results!$A$2:$A$2256,Results!G$2:G$2256,"") -> 0 | AM3: =_xlfn.XLOOKUP($A3,Results!$A$2:$A$2256,Results!H$2:H$2256,"") -> 0 | AN3: =_xlfn.XLOOKUP($A3,Results!$A$2:$A$2256,Results!I$2:I$2256,"") -> 0 | AO3: =_xlfn.XLOOKUP($A3,Results!$A$2:$A$2256,Results!J$2:J$2256,"") -> 0 | AP3: =_xlfn.XLOOKUP($A3,Results!$A$2:$A$2256,Results!K$2:K$2256,"") -> 0 | AQ3: =_xlfn.XLOOKUP($A3,Results!$A$2:$A$2256,Results!L$2:L$2256,"") -> 0 | AR3: =_xlfn.XLOOKUP($A3,Results!$A$2:$A$2256,Results!M$2:M$2256,"") -> 0 | AS3: =_xlfn.XLOOKUP($A3,Results!$A$2:$A$2256,Results!N$2:N$2256,"") -> 0 | ... BE3: =_xlfn.XLOOKUP($A3,Results!$A$2:$A$2256,Results!Z$2:Z$2256,"") -> 0
A4: 905681 | B4: 281955 | C4: NULL | D4: 9341430837 | E4: =VLOOKUP(F4,'RPA Vendor Data '!F2:$G$2418,2) -> GRAYBAR ELECTRIC CO. INC. | F4: 11471 | G4: 1 | H4: X CLOSE GENERIC VENDOR-TUBPA 3/4 3/4 X CLOSE-GALVANIZED CONDUIT NIPPLE | I4: 12 | J4: C | K4: C | L4: 148.05 | M4: GENERIC CONDUIT/CONDUIT FITTINGS | N4: 3/4 X CLOSE | O4: NULL | P4: AK10432182 | Q4: NULL | R4: 17.77 | S4: 45744.834 | T4: PA_SRDC | U4: 45744.619 | V4: PAUSER | W4: NULL | X4: 0 | Y4: 201 | Z4: NULL | AA4: NULL | AB4: NULL | AC4: GENERIC CONDUIT/CONDUIT FITTINGS | AD4: GENERIC CONDUIT/CONDUIT FITTINGS | AE4: AI | AF4: 39131718 | AG4: https://www.graybar.com/conduit-nipple-rigid-imc-galvanized-steel-3-4-x-close/p/88273326 | AI4: MATERIAL | AJ4: =VLOOKUP(A4,'Classification Test Result'!$A$2:$D$2428,4,FALSE) -> #N/A | AL4: =_xlfn.XLOOKUP($A4,Results!$A$2:$A$2256,Results!G$2:G$2256,"") -> 0 | AM4: =_xlfn.XLOOKUP($A4,Results!$A$2:$A$2256,Results!H$2:H$2256,"") -> 0 | AN4: =_xlfn.XLOOKUP($A4,Results!$A$2:$A$2256,Results!I$2:I$2256,"") -> 0 | AO4: =_xlfn.XLOOKUP($A4,Results!$A$2:$A$2256,Results!J$2:J$2256,"") -> 0 | AP4: =_xlfn.XLOOKUP($A4,Results!$A$2:$A$2256,Results!K$2:K$2256,"") -> 0 | AQ4: =_xlfn.XLOOKUP($A4,Results!$A$2:$A$2256,Results!L$2:L$2256,"") -> 0 | AR4: =_xlfn.XLOOKUP($A4,Results!$A$2:$A$2256,Results!M$2:M$2256,"") -> 0 | AS4: =_xlfn.XLOOKUP($A4,Results!$A$2:$A$2256,Results!N$2:N$2256,"") -> 0 | ... BE4: =_xlfn.XLOOKUP($A4,Results!$A$2:$A$2256,Results!Z$2:Z$2256,"") -> TRUE
A5: 905682 | B5: 281420 | C5: NULL | D5: S142066793.001 | E5: =VLOOKUP(F5,'RPA Vendor Data '!F3:$G$2418,2) -> REXEL USA, INC. | F5: 12873 | G5: 1 | H5: WS LMRC-211 770734 DIGITAL V.2 SGLE RELAY RM CONTROLLER ON/OFF 0-10V DIMM | I5: 2 | J5: EA | K5: E | L5: 209.816 | M5: WATTSTOPPER | N5: LMRC-211 | O5: 770734 | P5: NULL | Q5: NULL | R5: 419.63 | S5: 45744.271 | T5: PA_SRDC | U5: 45744.061 | V5: PAUSER | W5: NULL | X5: 0 | Y5: 201 | Z5: NULL | AA5: NULL | AB5: NULL | AC5: WATTSTOPPER | AD5: WATTSTOPPER | AE5: AI | AF5: - | AG5: https://www.rexelusa.com/p/770734/wattstopper/digital-room-controller-dimmer-single/754182929030/lmrc-211 | AI5: MATERIAL | AJ5: =VLOOKUP(A5,'Classification Test Result'!$A$2:$D$2428,4,FALSE) -> #N/A | AL5: =_xlfn.XLOOKUP($A5,Results!$A$2:$A$2256,Results!G$2:G$2256,"") -> 735909 | AM5: =_xlfn.XLOOKUP($A5,Results!$A$2:$A$2256,Results!H$2:H$2256,"") -> LMRC211 | AN5: =_xlfn.XLOOKUP($A5,Results!$A$2:$A$2256,Results!I$2:I$2256,"") -> WATTSTOPPER | AO5: =_xlfn.XLOOKUP($A5,Results!$A$2:$A$2256,Results!J$2:J$2256,"") -> 754182929030 | AP5: =_xlfn.XLOOKUP($A5,Results!$A$2:$A$2256,Results!K$2:K$2256,"") -> 45111808 | AQ5: =_xlfn.XLOOKUP($A5,Results!$A$2:$A$2256,Results!L$2:L$2256,"") -> 0 | AR5: =_xlfn.XLOOKUP($A5,Results!$A$2:$A$2256,Results!M$2:M$2256,"") -> 480852 | AS5: =_xlfn.XLOOKUP($A5,Results!$A$2:$A$2256,Results!N$2:N$2256,"") -> WATT LMRC-211 ROOM CTRLR | ... BE5: =_xlfn.XLOOKUP($A5,Results!$A$2:$A$2256,Results!Z$2:Z$2256,"") -> TRUE
A6: 905683 | B6: 281440 | C6: NULL | D6: S104532279.001 | E6: =VLOOKUP(F6,'RPA Vendor Data '!F4:$G$2418,2) -> DAKOTA SUPPLY GROUP | F6: 10942 | G6: 1 | H6: WRMLD LOT 729287 * Item not returnable without RGA * (4) WD10W350-60 (8) CP10-S30 (8) WD10W350-ECS | I6: 1 | J6: EA | K6: E | L6: 2182.031 | M6: WIREMOLD | N6: LOT | O6: 729287 | P6: NULL | Q6: NULL | R6: 2182.03 | S6: 45744.313 | T6: PA_SRDC | U6: 45744.088 | V6: PAUSER | W6: NULL | X6: 0 | Y6: 999 | Z6: NULL | AA6: NULL | AB6: NULL | AC6: UNDEFINED | AD6: UNDEFINED | AE6: AI | AF6: - | AG6: LOT | AH6: No | AI6: MATERIAL | AJ6: =VLOOKUP(A6,'Classification Test Result'!$A$2:$D$2428,4,FALSE) -> #N/A | AL6: =_xlfn.XLOOKUP($A6,Results!$A$2:$A$2256,Results!G$2:G$2256,"") -> 0 | AM6: =_xlfn.XLOOKUP($A6,Results!$A$2:$A$2256,Results!H$2:H$2256,"") -> 0 | AN6: =_xlfn.XLOOKUP($A6,Results!$A$2:$A$2256,Results!I$2:I$2256,"") -> 0 | AO6: =_xlfn.XLOOKUP($A6,Results!$A$2:$A$2256,Results!J$2:J$2256,"") -> 0 | AP6: =_xlfn.XLOOKUP($A6,Results!$A$2:$A$2256,Results!K$2:K$2256,"") -> 0 | AQ6: =_xlfn.XLOOKUP($A6,Results!$A$2:$A$2256,Results!L$2:L$2256,"") -> 0 | AR6: =_xlfn.XLOOKUP($A6,Results!$A$2:$A$2256,Results!M$2:M$2256,"") -> 0 | AS6: =_xlfn.XLOOKUP($A6,Results!$A$2:$A$2256,Results!N$2:N$2256,"") -> 0 | ... BE6: =_xlfn.XLOOKUP($A6,Results!$A$2:$A$2256,Results!Z$2:Z$2256,"") -> 0
A7: 905684 | B7: 281988 | C7: NULL | D7: S4741526.001 | E7: =VLOOKUP(F7,'RPA Vendor Data '!F5:$G$2418,2) -> FROST ELECTRIC SUPPLY CO | F7: 11364 | G7: 6 | H7: Wright 311 10PC Hex Bit Socket Set with 3/8 Drive Sizes 1/8 5/32 3/16 7/32 1/4 5/16 & 3/8, and 1/2 Drive Sizes 1/2 9/16 5/8 On Rail w/ 10 Clips | I7: 1 | J7: EA | K7: E | L7: 203.74 | M7: WRIGHT TOOL | N7: 311 | O7: NULL | P7: NULL | Q7: 76799003119 | R7: 203.74 | S7: 45744.897 | T7: PA_SRDC | U7: 45744.668 | V7: PAUSER | W7: NULL | X7: 10 | Y7: 201,0,0 | Z7: NULL | AA7: 203.74 | AB7: NULL | AC7: WRIGHT TOOL | AD7: WRIGHT TOOL | AE7: AI | AF7: - | AG7: https://www.zoro.com/wright-tool-38-drive-hex-bit-socket-set-sae-10-pcs-311/i/G2133618/?utm_source=google&utm_medium=surfaces&utm_campaign=shopping%20feed&utm_content=free%20google%20shopping%20clicks&campaignid=21528295865&productid=G2133618&v=&gad_source=1&gclid=EAIaIQobChMIo_uPm_rJjAMVkjEIBR0D7R-eEAQYASABEgLil_D_BwE&gclsrc=aw.ds | AI7: MATERIAL | AJ7: =VLOOKUP(A7,'Classification Test Result'!$A$2:$D$2428,4,FALSE) -> #N/A | AL7: =_xlfn.XLOOKUP($A7,Results!$A$2:$A$2256,Results!G$2:G$2256,"") -> 0 | AM7: =_xlfn.XLOOKUP($A7,Results!$A$2:$A$2256,Results!H$2:H$2256,"") -> 0 | AN7: =_xlfn.XLOOKUP($A7,Results!$A$2:$A$2256,Results!I$2:I$2256,"") -> 0 | AO7: =_xlfn.XLOOKUP($A7,Results!$A$2:$A$2256,Results!J$2:J$2256,"") -> 0 | AP7: =_xlfn.XLOOKUP($A7,Results!$A$2:$A$2256,Results!K$2:K$2256,"") -> 0 | AQ7: =_xlfn.XLOOKUP($A7,Results!$A$2:$A$2256,Results!L$2:L$2256,"") -> 0 | AR7: =_xlfn.XLOOKUP($A7,Results!$A$2:$A$2256,Results!M$2:M$2256,"") -> 0 | AS7: =_xlfn.XLOOKUP($A7,Results!$A$2:$A$2256,Results!N$2:N$2256,"") -> 0 | ... BE7: =_xlfn.XLOOKUP($A7,Results!$A$2:$A$2256,Results!Z$2:Z$2256,"") -> 0
A8: 905685 | B8: 281941 | C8: NULL | D8: 9341425462 | E8: =VLOOKUP(F8,'RPA Vendor Data '!F6:$G$2418,2) -> GRAYBAR ELECTRIC CO. INC. | F8: 11471 | G8: 2 | H8: WIREMOLD CO SGC2-RT SINGLE GANG COMM PLATE ORTRONICS | I8: 12 | J8: E | K8: E | L8: 9.05 | M8: WIREMOLD | N8: SGC2-RT | O8: NULL | P8: NULL | Q8: NULL | R8: 108.6 | S8: 45744.834 | T8: PA_SRDC | U8: 45744.617 | V8: PAUSER | W8: NULL | X8: 4 | Y8: 201,0,0 | Z8: NULL | AA8: 9.05 | AB8: NULL | AC8: WIREMOLD | AD8: WIREMOLD | AE8: AI | AF8: 39121307 | AG8: https://www.graybar.com/saf2-1-2-series-communication-plate/p/22044847?pcode=22044847 | AI8: MATERIAL | AJ8: =VLOOKUP(A8,'Classification Test Result'!$A$2:$D$2428,4,FALSE) -> #N/A | AL8: =_xlfn.XLOOKUP($A8,Results!$A$2:$A$2256,Results!G$2:G$2256,"") -> 0 | AM8: =_xlfn.XLOOKUP($A8,Results!$A$2:$A$2256,Results!H$2:H$2256,"") -> 0 | AN8: =_xlfn.XLOOKUP($A8,Results!$A$2:$A$2256,Results!I$2:I$2256,"") -> 0 | AO8: =_xlfn.XLOOKUP($A8,Results!$A$2:$A$2256,Results!J$2:J$2256,"") -> 0 | AP8: =_xlfn.XLOOKUP($A8,Results!$A$2:$A$2256,Results!K$2:K$2256,"") -> 0 | AQ8: =_xlfn.XLOOKUP($A8,Results!$A$2:$A$2256,Results!L$2:L$2256,"") -> 0 | AR8: =_xlfn.XLOOKUP($A8,Results!$A$2:$A$2256,Results!M$2:M$2256,"") -> 0 | AS8: =_xlfn.XLOOKUP($A8,Results!$A$2:$A$2256,Results!N$2:N$2256,"") -> 0 | ... BE8: =_xlfn.XLOOKUP($A8,Results!$A$2:$A$2256,Results!Z$2:Z$2256,"") -> TRUE
A9: 905686 | B9: 281941 | C9: NULL | D9: 9341425462 | E9: =VLOOKUP(F9,'RPA Vendor Data '!F7:$G$2418,2) -> GRAYBAR ELECTRIC CO. INC. | F9: 11471 | G9: 1 | H9: WIREMOLD CO SGC2-ACT SINGLE GANG COMM PLT ACTIVATE | I9: 12 | J9: E | K9: E | L9: 8.32 | M9: WIREMOLD | N9: SGC2-ACT | O9: NULL | P9: NULL | Q9: NULL | R9: 99.84 | S9: 45744.834 | T9: PA_SRDC | U9: 45744.617 | V9: PAUSER | W9: NULL | X9: 3 | Y9: 201,0,0 | Z9: NULL | AA9: 8.32 | AB9: NULL | AC9: WIREMOLD | AD9: WIREMOLD | AE9: AI | AF9: 39121307 | AG9: https://www.graybar.com/saf2-1-2-series-communication-plate-1-gang/p/22044849 | AI9: MATERIAL | AJ9: =VLOOKUP(A9,'Classification Test Result'!$A$2:$D$2428,4,FALSE) -> #N/A | AL9: =_xlfn.XLOOKUP($A9,Results!$A$2:$A$2256,Results!G$2:G$2256,"") -> 0 | AM9: =_xlfn.XLOOKUP($A9,Results!$A$2:$A$2256,Results!H$2:H$2256,"") -> 0 | AN9: =_xlfn.XLOOKUP($A9,Results!$A$2:$A$2256,Results!I$2:I$2256,"") -> 0 | AO9: =_xlfn.XLOOKUP($A9,Results!$A$2:$A$2256,Results!J$2:J$2256,"") -> 0 | AP9: =_xlfn.XLOOKUP($A9,Results!$A$2:$A$2256,Results!K$2:K$2256,"") -> 0 | AQ9: =_xlfn.XLOOKUP($A9,Results!$A$2:$A$2256,Results!L$2:L$2256,"") -> 0 | AR9: =_xlfn.XLOOKUP($A9,Results!$A$2:$A$2256,Results!M$2:M$2256,"") -> 0 | AS9: =_xlfn.XLOOKUP($A9,Results!$A$2:$A$2256,Results!N$2:N$2256,"") -> 0 | ... BE9: =_xlfn.XLOOKUP($A9,Results!$A$2:$A$2256,Results!Z$2:Z$2256,"") -> 0
A10: 905687 | B10: 281391 | C10: NULL | D10: 9341431311 | E10: =VLOOKUP(F10,'RPA Vendor Data '!F8:$G$2418,2) -> GRAYBAR ELECTRIC CO. INC. | F10: 11471 | G10: 1 | H10: WIREMOLD CO NP800C-10-2B NP800 ANOD POLE 10FT.2IN.L WBOX END | I10: 4 | J10: E | K10: E | L10: 708.15 | M10: WIREMOLD | N10: NP800C-10-2B | O10: NULL | P10: NULL | Q10: NULL | R10: 2832.6 | S10: 45744.272 | T10: PA_SRDC | U10: 45744.053 | V10: PAUSER | W10: NULL | X10: 0 | Y10: 201,0,0 | Z10: NULL | AA10: 708.15 | AB10: NULL | AC10: WIREMOLD | AD10: WIREMOLD | AE10: AI | AF10: 39131713 | AG10: https://www.graybar.com/power-pole-aluminum-np800-tele-power-10-ft-2-in/p/25872612?pcode=25872612 | AI10: MATERIAL | AJ10: =VLOOKUP(A10,'Classification Test Result'!$A$2:$D$2428,4,FALSE) -> #N/A | AL10: =_xlfn.XLOOKUP($A10,Results!$A$2:$A$2256,Results!G$2:G$2256,"") -> 0 | AM10: =_xlfn.XLOOKUP($A10,Results!$A$2:$A$2256,Results!H$2:H$2256,"") -> 0 | AN10: =_xlfn.XLOOKUP($A10,Results!$A$2:$A$2256,Results!I$2:I$2256,"") -> 0 | AO10: =_xlfn.XLOOKUP($A10,Results!$A$2:$A$2256,Results!J$2:J$2256,"") -> 0 | AP10: =_xlfn.XLOOKUP($A10,Results!$A$2:$A$2256,Results!K$2:K$2256,"") -> 0 | AQ10: =_xlfn.XLOOKUP($A10,Results!$A$2:$A$2256,Results!L$2:L$2256,"") -> 0 | AR10: =_xlfn.XLOOKUP($A10,Results!$A$2:$A$2256,Results!M$2:M$2256,"") -> 0 | AS10: =_xlfn.XLOOKUP($A10,Results!$A$2:$A$2256,Results!N$2:N$2256,"") -> 0 | ... BE10: =_xlfn.XLOOKUP($A10,Results!$A$2:$A$2256,Results!Z$2:Z$2256,"") -> 0
A11: 905688 | B11: 281931 | C11: NULL | D11: 27MAR2025-109766 | F11: 16374 | G11: 2 | H11: WS (Winter Service Charge - Nov 1 - Mar 31) | I11: 40 | J11: E | K11: E | L11: 10 | M11: NULL | N11: NULL | O11: NULL | P11: NULL | Q11: NULL | R11: 400 | S11: 45744.813 | T11: PA_SRDC | U11: 45744.595 | V11: PAUSER | W11: NULL | X11: 0 | Y11: 999 | Z11: NULL | AA11: NULL | AB11: NULL | AC11: UNDEFINED | AD11: UNDEFINED | AE11: AI | AI11: FEE | AJ11: =VLOOKUP(A11,'Classification Test Result'!$A$2:$D$2428,4,FALSE) -> #N/A | AL11: =_xlfn.XLOOKUP($A11,Results!$A$2:$A$2256,Results!G$2:G$2256,"") -> 0 | AM11: =_xlfn.XLOOKUP($A11,Results!$A$2:$A$2256,Results!H$2:H$2256,"") -> 0 | AN11: =_xlfn.XLOOKUP($A11,Results!$A$2:$A$2256,Results!I$2:I$2256,"") -> 0 | AO11: =_xlfn.XLOOKUP($A11,Results!$A$2:$A$2256,Results!J$2:J$2256,"") -> 0 | AP11: =_xlfn.XLOOKUP($A11,Results!$A$2:$A$2256,Results!K$2:K$2256,"") -> 0 | AQ11: =_xlfn.XLOOKUP($A11,Results!$A$2:$A$2256,Results!L$2:L$2256,"") -> 0 | AR11: =_xlfn.XLOOKUP($A11,Results!$A$2:$A$2256,Results!M$2:M$2256,"") -> 0 | AS11: =_xlfn.XLOOKUP($A11,Results!$A$2:$A$2256,Results!N$2:N$2256,"") -> 0 | ... BE11: =_xlfn.XLOOKUP($A11,Results!$A$2:$A$2256,Results!Z$2:Z$2256,"") -> 0
A12: 905689 | B12: 281813 | C12: NULL | D12: 25MAR2025-109577 | F12: 16374 | G12: 2 | H12: WS (Winter Service Charge - Nov 1 - Mar 31) | I12: 30 | J12: E | K12: E | L12: 10 | M12: NULL | N12: NULL | O12: NULL | P12: NULL | Q12: NULL | R12: 300 | S12: 45744.605 | T12: PA_SRDC | U12: 45744.385 | V12: PAUSER | W12: NULL | X12: 0 | Y12: 999 | Z12: NULL | AA12: NULL | AB12: NULL | AC12: UNDEFINED | AD12: UNDEFINED | AE12: AI | AI12: FEE | AJ12: =VLOOKUP(A12,'Classification Test Result'!$A$2:$D$2428,4,FALSE) -> #N/A | AL12: =_xlfn.XLOOKUP($A12,Results!$A$2:$A$2256,Results!G$2:G$2256,"") -> 0 | AM12: =_xlfn.XLOOKUP($A12,Results!$A$2:$A$2256,Results!H$2:H$2256,"") -> 0 | AN12: =_xlfn.XLOOKUP($A12,Results!$A$2:$A$2256,Results!I$2:I$2256,"") -> 0 | AO12: =_xlfn.XLOOKUP($A12,Results!$A$2:$A$2256,Results!J$2:J$2256,"") -> 0 | AP12: =_xlfn.XLOOKUP($A12,Results!$A$2:$A$2256,Results!K$2:K$2256,"") -> 0 | AQ12: =_xlfn.XLOOKUP($A12,Results!$A$2:$A$2256,Results!L$2:L$2256,"") -> 0 | AR12: =_xlfn.XLOOKUP($A12,Results!$A$2:$A$2256,Results!M$2:M$2256,"") -> 0 | AS12: =_xlfn.XLOOKUP($A12,Results!$A$2:$A$2256,Results!N$2:N$2256,"") -> 0 | ... BE12: =_xlfn.XLOOKUP($A12,Results!$A$2:$A$2256,Results!Z$2:Z$2256,"") -> 0
A13: 905690 | B13: 281815 | C13: NULL | D13: 26MAR2025-109682 | F13: 16374 | G13: 2 | H13: WS (Winter Service Charge - Nov 1 - Mar 31) | I13: 50 | J13: E | K13: E | L13: 10 | M13: NULL | N13: NULL | O13: NULL | P13: NULL | Q13: NULL | R13: 500 | S13: 45744.605 | T13: PA_SRDC | U13: 45744.387 | V13: PAUSER | W13: NULL | X13: 0 | Y13: 999 | Z13: NULL | AA13: NULL | AB13: NULL | AC13: UNDEFINED | AD13: UNDEFINED | AE13: AI | AI13: FEE | AJ13: =VLOOKUP(A13,'Classification Test Result'!$A$2:$D$2428,4,FALSE) -> #N/A | AL13: =_xlfn.XLOOKUP($A13,Results!$A$2:$A$2256,Results!G$2:G$2256,"") -> 0 | AM13: =_xlfn.XLOOKUP($A13,Results!$A$2:$A$2256,Results!H$2:H$2256,"") -> 0 | AN13: =_xlfn.XLOOKUP($A13,Results!$A$2:$A$2256,Results!I$2:I$2256,"") -> 0 | AO13: =_xlfn.XLOOKUP($A13,Results!$A$2:$A$2256,Results!J$2:J$2256,"") -> 0 | AP13: =_xlfn.XLOOKUP($A13,Results!$A$2:$A$2256,Results!K$2:K$2256,"") -> 0 | AQ13: =_xlfn.XLOOKUP($A13,Results!$A$2:$A$2256,Results!L$2:L$2256,"") -> 0 | AR13: =_xlfn.XLOOKUP($A13,Results!$A$2:$A$2256,Results!M$2:M$2256,"") -> 0 | AS13: =_xlfn.XLOOKUP($A13,Results!$A$2:$A$2256,Results!N$2:N$2256,"") -> 0 | ... BE13: =_xlfn.XLOOKUP($A13,Results!$A$2:$A$2256,Results!Z$2:Z$2256,"") -> 0
A14: 905691 | B14: 281666 | C14: NULL | D14: S013772528.001 | E14: =VLOOKUP(F14,'RPA Vendor Data '!F9:$G$2418,2) -> VAN METER, INC. | F14: 13513 | G14: 1 | H14: WIRE-LINE 12550 1/2 STAPLE 500/BAG | I14: 500 | J14: m | K14: M | L14: 46.784 | M14: WIRE-LINE | N14: 12550 | O14: NULL | P14: NULL | Q14: 60550512550 | R14: 23.39 | S14: 45744.501 | T14: PA_SRDC | U14: 45744.282 | V14: PAUSER | W14: NULL | X14: 0 | Y14: 999 | Z14: NULL | AA14: NULL | AB14: NULL | AC14: UNDEFINED | AD14: UNDEFINED | AE14: AI | AF14: - | AG14: https://www.arcasupply.com/e27-7303/?srsltid=AfmBOor6FL2JUJCWR6beBKVWtuMh4c-5BwEaSyXlOWdR0cQ1Zajc6J8Q | AI14: MATERIAL | AJ14: =VLOOKUP(A14,'Classification Test Result'!$A$2:$D$2428,4,FALSE) -> #N/A | AK14: I can't find this item | AL14: =_xlfn.XLOOKUP($A14,Results!$A$2:$A$2256,Results!G$2:G$2256,"") -> 0 | AM14: =_xlfn.XLOOKUP($A14,Results!$A$2:$A$2256,Results!H$2:H$2256,"") -> 0 | AN14: =_xlfn.XLOOKUP($A14,Results!$A$2:$A$2256,Results!I$2:I$2256,"") -> 0 | AO14: =_xlfn.XLOOKUP($A14,Results!$A$2:$A$2256,Results!J$2:J$2256,"") -> 0 | AP14: =_xlfn.XLOOKUP($A14,Results!$A$2:$A$2256,Results!K$2:K$2256,"") -> 0 | AQ14: =_xlfn.XLOOKUP($A14,Results!$A$2:$A$2256,Results!L$2:L$2256,"") -> 0 | AR14: =_xlfn.XLOOKUP($A14,Results!$A$2:$A$2256,Results!M$2:M$2256,"") -> 0 | AS14: =_xlfn.XLOOKUP($A14,Results!$A$2:$A$2256,Results!N$2:N$2256,"") -> 0 | ... BE14: =_xlfn.XLOOKUP($A14,Results!$A$2:$A$2256,Results!Z$2:Z$2256,"") -> 0
A15: 905692 | B15: 281597 | C15: NULL | D15: S013772528.001 | E15: =VLOOKUP(F15,'RPA Vendor Data '!F10:$G$2418,2) -> VAN METER, INC. | F15: 13513 | G15: 1 | H15: WIRE-LINE 12550 1/2 STAPLE 500/BAG | I15: 500 | J15: m | K15: M | L15: 46.784 | M15: WIRE-LINE | N15: 12550 | O15: NULL | P15: NULL | Q15: 60550512550 | R15: 23.39 | S15: 45744.481 | T15: PA_SRDC | U15: 45744.251 | V15: PAUSER | W15: NULL | X15: 0 | Y15: 201,0,0 | Z15: NULL | AA15: 46.8 | AB15: NULL | AC15: UNDEFINED | AD15: UNDEFINED | AE15: AI | AF15: - | AG15: https://www.arcasupply.com/e27-7303/?srsltid=AfmBOor6FL2JUJCWR6beBKVWtuMh4c-5BwEaSyXlOWdR0cQ1Zajc6J8Q | AI15: MATERIAL | AJ15: =VLOOKUP(A15,'Classification Test Result'!$A$2:$D$2428,4,FALSE) -> #N/A | AK15: I can't find this item | AL15: =_xlfn.XLOOKUP($A15,Results!$A$2:$A$2256,Results!G$2:G$2256,"") -> 0 | AM15: =_xlfn.XLOOKUP($A15,Results!$A$2:$A$2256,Results!H$2:H$2256,"") -> 0 | AN15: =_xlfn.XLOOKUP($A15,Results!$A$2:$A$2256,Results!I$2:I$2256,"") -> 0 | AO15: =_xlfn.XLOOKUP($A15,Results!$A$2:$A$2256,Results!J$2:J$2256,"") -> 0 | AP15: =_xlfn.XLOOKUP($A15,Results!$A$2:$A$2256,Results!K$2:K$2256,"") -> 0 | AQ15: =_xlfn.XLOOKUP($A15,Results!$A$2:$A$2256,Results!L$2:L$2256,"") -> 0 | AR15: =_xlfn.XLOOKUP($A15,Results!$A$2:$A$2256,Results!M$2:M$2256,"") -> 0 | AS15: =_xlfn.XLOOKUP($A15,Results!$A$2:$A$2256,Results!N$2:N$2256,"") -> 0 | ... BE15: =_xlfn.XLOOKUP($A15,Results!$A$2:$A$2256,Results!Z$2:Z$2256,"") -> 0
A16: 905693 | B16: 281609 | C16: NULL | D16: S013772528.001 | E16: =VLOOKUP(F16,'RPA Vendor Data '!F11:$G$2418,2) -> VAN METER, INC. | F16: 13513 | G16: 1 | H16: WIRE-LINE 12550 1/2 STAPLE 500/BAG | I16: 500 | J16: m | K16: M | L16: 46.784 | M16: WIRE-LINE | N16: 12550 | O16: NULL | P16: NULL | Q16: 60550512550 | R16: 23.39 | S16: 45744.481 | T16: PA_SRDC | U16: 45744.253 | V16: PAUSER | W16: NULL | X16: 0 | Y16: 999 | Z16: NULL | AA16: NULL | AB16: NULL | AC16: UNDEFINED | AD16: UNDEFINED | AE16: AI | AF16: - | AG16: https://www.arcasupply.com/e27-7303/?srsltid=AfmBOor6FL2JUJCWR6beBKVWtuMh4c-5BwEaSyXlOWdR0cQ1Zajc6J8Q | AI16: MATERIAL | AJ16: =VLOOKUP(A16,'Classification Test Result'!$A$2:$D$2428,4,FALSE) -> #N/A | AK16: I can't find this item | AL16: =_xlfn.XLOOKUP($A16,Results!$A$2:$A$2256,Results!G$2:G$2256,"") -> 0 | AM16: =_xlfn.XLOOKUP($A16,Results!$A$2:$A$2256,Results!H$2:H$2256,"") -> 0 | AN16: =_xlfn.XLOOKUP($A16,Results!$A$2:$A$2256,Results!I$2:I$2256,"") -> 0 | AO16: =_xlfn.XLOOKUP($A16,Results!$A$2:$A$2256,Results!J$2:J$2256,"") -> 0 | AP16: =_xlfn.XLOOKUP($A16,Results!$A$2:$A$2256,Results!K$2:K$2256,"") -> 0 | AQ16: =_xlfn.XLOOKUP($A16,Results!$A$2:$A$2256,Results!L$2:L$2256,"") -> 0 | AR16: =_xlfn.XLOOKUP($A16,Results!$A$2:$A$2256,Results!M$2:M$2256,"") -> 0 | AS16: =_xlfn.XLOOKUP($A16,Results!$A$2:$A$2256,Results!N$2:N$2256,"") -> 0 | ... BE16: =_xlfn.XLOOKUP($A16,Results!$A$2:$A$2256,Results!Z$2:Z$2256,"") -> 0
A17: 905694 | B17: 281618 | C17: NULL | D17: S013772528.001 | E17: =VLOOKUP(F17,'RPA Vendor Data '!F12:$G$2418,2) -> VAN METER, INC. | F17: 13513 | G17: 1 | H17: WIRE-LINE 12550 1/2 STAPLE 500/BAG | I17: 500 | J17: m | K17: M | L17: 46.784 | M17: WIRE-LINE | N17: 12550 | O17: NULL | P17: NULL | Q17: 60550512550 | R17: 23.39 | S17: 45744.48 | T17: PA_SRDC | U17: 45744.263 | V17: PAUSER | W17: NULL | X17: 0 | Y17: 999 | Z17: NULL | AA17: NULL | AB17: NULL | AC17: UNDEFINED | AD17: UNDEFINED | AE17: AI | AF17: - | AG17: https://www.arcasupply.com/e27-7303/?srsltid=AfmBOor6FL2JUJCWR6beBKVWtuMh4c-5BwEaSyXlOWdR0cQ1Zajc6J8Q | AI17: MATERIAL | AJ17: =VLOOKUP(A17,'Classification Test Result'!$A$2:$D$2428,4,FALSE) -> #N/A | AK17: I can't find this item | AL17: =_xlfn.XLOOKUP($A17,Results!$A$2:$A$2256,Results!G$2:G$2256,"") -> 0 | AM17: =_xlfn.XLOOKUP($A17,Results!$A$2:$A$2256,Results!H$2:H$2256,"") -> 0 | AN17: =_xlfn.XLOOKUP($A17,Results!$A$2:$A$2256,Results!I$2:I$2256,"") -> 0 | AO17: =_xlfn.XLOOKUP($A17,Results!$A$2:$A$2256,Results!J$2:J$2256,"") -> 0 | AP17: =_xlfn.XLOOKUP($A17,Results!$A$2:$A$2256,Results!K$2:K$2256,"") -> 0 | AQ17: =_xlfn.XLOOKUP($A17,Results!$A$2:$A$2256,Results!L$2:L$2256,"") -> 0 | AR17: =_xlfn.XLOOKUP($A17,Results!$A$2:$A$2256,Results!M$2:M$2256,"") -> 0 | AS17: =_xlfn.XLOOKUP($A17,Results!$A$2:$A$2256,Results!N$2:N$2256,"") -> 0 | ... BE17: =_xlfn.XLOOKUP($A17,Results!$A$2:$A$2256,Results!Z$2:Z$2256,"") -> 0
A18: 905695 | B18: 282041 | C18: NULL | D18: S6404142.001 | E18: =VLOOKUP(F18,'RPA Vendor Data '!F13:$G$2418,2) -> EDGES ELECTRICAL GROUP | F18: 16768 | G18: 1 | H18: WIRE THHN4-GRY-STR-CU CUT | I18: 115 | J18: M | K18: M | L18: 1190 | M18: GENERIC WIRE | N18: THHN-4-STR19-GRY-CU | O18: NULL | P18: NULL | Q18: NULL | R18: 136.85 | S18: 45744.938 | T18: PA_SRDC | U18: 45744.71 | V18: PAUSER | W18: NULL | X18: 0 | Y18: 201 | Z18: NULL | AA18: NULL | AB18: NULL | AC18: GENERIC WIRE | AD18: GENERIC WIRE | AE18: AI | AF18: 26121614 | AG18: https://www.edgesgroup.com/buy/product/wire-thhn4-gry-str-cu-cut/1793558 | AI18: MATERIAL | AJ18: =VLOOKUP(A18,'Classification Test Result'!$A$2:$D$2428,4,FALSE) -> #N/A | AK18: No specified Wire manufcaturer | AL18: =_xlfn.XLOOKUP($A18,Results!$A$2:$A$2256,Results!G$2:G$2256,"") -> 0 | AM18: =_xlfn.XLOOKUP($A18,Results!$A$2:$A$2256,Results!H$2:H$2256,"") -> 0 | AN18: =_xlfn.XLOOKUP($A18,Results!$A$2:$A$2256,Results!I$2:I$2256,"") -> 0 | AO18: =_xlfn.XLOOKUP($A18,Results!$A$2:$A$2256,Results!J$2:J$2256,"") -> 0 | AP18: =_xlfn.XLOOKUP($A18,Results!$A$2:$A$2256,Results!K$2:K$2256,"") -> 0 | AQ18: =_xlfn.XLOOKUP($A18,Results!$A$2:$A$2256,Results!L$2:L$2256,"") -> 0 | AR18: =_xlfn.XLOOKUP($A18,Results!$A$2:$A$2256,Results!M$2:M$2256,"") -> 0 | AS18: =_xlfn.XLOOKUP($A18,Results!$A$2:$A$2256,Results!N$2:N$2256,"") -> 0 | ... BE18: =_xlfn.XLOOKUP($A18,Results!$A$2:$A$2256,Results!Z$2:Z$2256,"") -> TRUE
A19: 905696 | B19: 281779 | C19: NULL | D19: S103407780.001 | E19: =VLOOKUP(F19,'RPA Vendor Data '!F14:$G$2418,2) -> LOEB ELECTRIC | F19: 12062 | G19: 1 | H19: WIRE BARE-SD-6-SOL-CU-5000MSTR Cuts: 5 @ 1000 ft | I19: 5000 | J19: m | K19: M | L19: 696.374 | M19: GENERIC WIRE | N19: BARE-CU-SD-6-SOL-CUT REEL | O19: NULL | P19: NULL | Q19: NULL | R19: 3481.87 | S19: 45744.565 | T19: PA_SRDC | U19: 45744.35 | V19: PAUSER | W19: NULL | X19: 0 | Y19: 999 | Z19: NULL | AA19: NULL | AB19: NULL | AC19: GENERIC WIRE | AD19: GENERIC WIRE | AE19: AI | AF19: 26121645 | AG19: https://www.graybar.com/bare-copper-wire-cut-reel-copper-solid-6-awg/p/22061327 | AI19: MATERIAL | AJ19: =VLOOKUP(A19,'Classification Test Result'!$A$2:$D$2428,4,FALSE) -> #N/A | AL19: =_xlfn.XLOOKUP($A19,Results!$A$2:$A$2256,Results!G$2:G$2256,"") -> 0 | AM19: =_xlfn.XLOOKUP($A19,Results!$A$2:$A$2256,Results!H$2:H$2256,"") -> 0 | AN19: =_xlfn.XLOOKUP($A19,Results!$A$2:$A$2256,Results!I$2:I$2256,"") -> 0 | AO19: =_xlfn.XLOOKUP($A19,Results!$A$2:$A$2256,Results!J$2:J$2256,"") -> 0 | AP19: =_xlfn.XLOOKUP($A19,Results!$A$2:$A$2256,Results!K$2:K$2256,"") -> 0 | AQ19: =_xlfn.XLOOKUP($A19,Results!$A$2:$A$2256,Results!L$2:L$2256,"") -> 0 | AR19: =_xlfn.XLOOKUP($A19,Results!$A$2:$A$2256,Results!M$2:M$2256,"") -> 0 | AS19: =_xlfn.XLOOKUP($A19,Results!$A$2:$A$2256,Results!N$2:N$2256,"") -> 0 | ... BE19: =_xlfn.XLOOKUP($A19,Results!$A$2:$A$2256,Results!Z$2:Z$2256,"") -> TRUE
A20: 905697 | B20: 281986 | C20: NULL | D20: S4743676.001 | E20: =VLOOKUP(F20,'RPA Vendor Data '!F17:$G$2418,2) -> FROST ELECTRIC SUPPLY CO | F20: 11364 | G20: 3 | H20: Wire 8 AWG Yellow THHN Stranded 500 Foot Reel 600 Volt Copper Wire | I20: 500 | J20: M | K20: M | L20: 547.2 | M20: GENERIC WIRE | N20: THHN-8-STR19-YEL-CU-500S/R | O20: NULL | P20: AK10439071 | Q20: 98010023125 | R20: 273.6 | S20: 45744.897 | T20: PA_SRDC | U20: 45744.667 | V20: PAUSER | W20: NULL | X20: 0 | Y20: 201,0,0 | Z20: NULL | AA20: 547.2 | AB20: NULL | AC20: GENERIC WIRE | AD20: GENERIC WIRE | AE20: AI | AF20: - | AG20: https://www.frostelectric.com/buy/product/wire-8/625880?text=Wire+8+AWG+Yellow+THHN+Stranded+500+Foot+Reel+600+Volt+Copper+Wire | AI20: MATERIAL | AJ20: =VLOOKUP(A20,'Classification Test Result'!$A$2:$D$2428,4,FALSE) -> #N/A | AL20: =_xlfn.XLOOKUP($A20,Results!$A$2:$A$2256,Results!G$2:G$2256,"") -> 0 | AM20: =_xlfn.XLOOKUP($A20,Results!$A$2:$A$2256,Results!H$2:H$2256,"") -> 0 | AN20: =_xlfn.XLOOKUP($A20,Results!$A$2:$A$2256,Results!I$2:I$2256,"") -> 0 | AO20: =_xlfn.XLOOKUP($A20,Results!$A$2:$A$2256,Results!J$2:J$2256,"") -> 0 | AP20: =_xlfn.XLOOKUP($A20,Results!$A$2:$A$2256,Results!K$2:K$2256,"") -> 0 | AQ20: =_xlfn.XLOOKUP($A20,Results!$A$2:$A$2256,Results!L$2:L$2256,"") -> 0 | AR20: =_xlfn.XLOOKUP($A20,Results!$A$2:$A$2256,Results!M$2:M$2256,"") -> 0 | AS20: =_xlfn.XLOOKUP($A20,Results!$A$2:$A$2256,Results!N$2:N$2256,"") -> 0 | ... BE20: =_xlfn.XLOOKUP($A20,Results!$A$2:$A$2256,Results!Z$2:Z$2256,"") -> 0
A21: 905698 | B21: 281986 | C21: NULL | D21: S4743676.001 | E21: =VLOOKUP(F21,'RPA Vendor Data '!F18:$G$2418,2) -> FROST ELECTRIC SUPPLY CO | F21: 11364 | G21: 2 | H21: Wire 8 AWG Orange THHN Stranded 500 Foot Reel 600 Volt Copper Wire | I21: 500 | J21: M | K21: M | L21: 547.2 | M21: GENERIC WIRE | N21: THHN-8-STR19-ORN-CU-500S/R | O21: NULL | P21: AK10439058 | Q21: 98010023145 | R21: 273.6 | S21: 45744.897 | T21: PA_SRDC | U21: 45744.667 | V21: PAUSER | W21: NULL | X21: 0 | Y21: 201,0,0 | Z21: NULL | AA21: 547.2 | AB21: NULL | AC21: GENERIC WIRE | AD21: GENERIC WIRE | AE21: AI | AF21: - | AG21: https://www.frostelectric.com/buy/product/wire-8/625872?text=Wire+8+AWG+Orange+THHN+Stranded+500+Foot+Reel+600+Volt+Copper+Wire | AI21: MATERIAL | AJ21: =VLOOKUP(A21,'Classification Test Result'!$A$2:$D$2428,4,FALSE) -> #N/A | AL21: =_xlfn.XLOOKUP($A21,Results!$A$2:$A$2256,Results!G$2:G$2256,"") -> 0 | AM21: =_xlfn.XLOOKUP($A21,Results!$A$2:$A$2256,Results!H$2:H$2256,"") -> 0 | AN21: =_xlfn.XLOOKUP($A21,Results!$A$2:$A$2256,Results!I$2:I$2256,"") -> 0 | AO21: =_xlfn.XLOOKUP($A21,Results!$A$2:$A$2256,Results!J$2:J$2256,"") -> 0 | AP21: =_xlfn.XLOOKUP($A21,Results!$A$2:$A$2256,Results!K$2:K$2256,"") -> 0 | AQ21: =_xlfn.XLOOKUP($A21,Results!$A$2:$A$2256,Results!L$2:L$2256,"") -> 0 | AR21: =_xlfn.XLOOKUP($A21,Results!$A$2:$A$2256,Results!M$2:M$2256,"") -> 0 | AS21: =_xlfn.XLOOKUP($A21,Results!$A$2:$A$2256,Results!N$2:N$2256,"") -> 0 | ... BE21: =_xlfn.XLOOKUP($A21,Results!$A$2:$A$2256,Results!Z$2:Z$2256,"") -> 0
A22: 905699 | B22: 281986 | C22: NULL | D22: S4743676.001 | E22: =VLOOKUP(F22,'RPA Vendor Data '!F19:$G$2418,2) -> FROST ELECTRIC SUPPLY CO | F22: 11364 | G22: 1 | H22: Wire 8 AWG Brown THHN Stranded 500 Foot Reel 600 Volt Copper Wire | I22: 500 | J22: M | K22: M | L22: 547.2 | M22: GENERIC WIRE | N22: THHN-8-STR19-BRN-CU-500S/R | O22: NULL | P22: AK10439049 | Q22: 98010023115 | R22: 273.6 | S22: 45744.897 | T22: PA_SRDC | U22: 45744.667 | V22: PAUSER | W22: NULL | X22: 0 | Y22: 201,0,0 | Z22: NULL | AA22: 547.2 | AB22: NULL | AC22: GENERIC WIRE | AD22: GENERIC WIRE | AE22: AI | AF22: - | AG22: https://www.frostelectric.com/buy/product/wire-8/369661?text=Wire+8+AWG+Brown+THHN+Stranded+500+Foot+Reel+600+Volt+Copper+Wire | AI22: MATERIAL | AJ22: =VLOOKUP(A22,'Classification Test Result'!$A$2:$D$2428,4,FALSE) -> #N/A | AL22: =_xlfn.XLOOKUP($A22,Results!$A$2:$A$2256,Results!G$2:G$2256,"") -> 0 | AM22: =_xlfn.XLOOKUP($A22,Results!$A$2:$A$2256,Results!H$2:H$2256,"") -> 0 | AN22: =_xlfn.XLOOKUP($A22,Results!$A$2:$A$2256,Results!I$2:I$2256,"") -> 0 | AO22: =_xlfn.XLOOKUP($A22,Results!$A$2:$A$2256,Results!J$2:J$2256,"") -> 0 | AP22: =_xlfn.XLOOKUP($A22,Results!$A$2:$A$2256,Results!K$2:K$2256,"") -> 0 | AQ22: =_xlfn.XLOOKUP($A22,Results!$A$2:$A$2256,Results!L$2:L$2256,"") -> 0 | AR22: =_xlfn.XLOOKUP($A22,Results!$A$2:$A$2256,Results!M$2:M$2256,"") -> 0 | AS22: =_xlfn.XLOOKUP($A22,Results!$A$2:$A$2256,Results!N$2:N$2256,"") -> 0 | ... BE22: =_xlfn.XLOOKUP($A22,Results!$A$2:$A$2256,Results!Z$2:Z$2256,"") -> TRUE
A23: 905700 | B23: 281962 | C23: NULL | D23: S4742832.001 | E23: =VLOOKUP(F23,'RPA Vendor Data '!F20:$G$2418,2) -> FROST ELECTRIC SUPPLY CO | F23: 11364 | G23: 1 | H23: Wire 12 AWG White THHN Stranded 500 Foot Reel 600 Volt Copper Wire | I23: 1000 | J23: M | K23: M | L23: 175.98 | M23: GENERIC WIRE | N23: THHN-12-STR19-WHT-CU-500S/R | O23: NULL | P23: NULL | Q23: NULL | R23: 175.98 | S23: 45744.876 | T23: PA_SRDC | U23: 45744.662 | V23: PAUSER | W23: NULL | X23: 0 | Y23: 201 | Z23: NULL | AA23: NULL | AB23: NULL | AC23: GENERIC WIRE | AD23: GENERIC WIRE | AE23: AI | AF23: - | AG23: https://www.frostelectric.com/buy/product/wire-12/12001?text=Wire+12+AWG+White+THHN+Stranded+500+Foot+Reel+600+Volt+Copper+Wire | AI23: MATERIAL | AJ23: =VLOOKUP(A23,'Classification Test Result'!$A$2:$D$2428,4,FALSE) -> #N/A | AL23: =_xlfn.XLOOKUP($A23,Results!$A$2:$A$2256,Results!G$2:G$2256,"") -> 0 | AM23: =_xlfn.XLOOKUP($A23,Results!$A$2:$A$2256,Results!H$2:H$2256,"") -> 0 | AN23: =_xlfn.XLOOKUP($A23,Results!$A$2:$A$2256,Results!I$2:I$2256,"") -> 0 | AO23: =_xlfn.XLOOKUP($A23,Results!$A$2:$A$2256,Results!J$2:J$2256,"") -> 0 | AP23: =_xlfn.XLOOKUP($A23,Results!$A$2:$A$2256,Results!K$2:K$2256,"") -> 0 | AQ23: =_xlfn.XLOOKUP($A23,Results!$A$2:$A$2256,Results!L$2:L$2256,"") -> 0 | AR23: =_xlfn.XLOOKUP($A23,Results!$A$2:$A$2256,Results!M$2:M$2256,"") -> 0 | AS23: =_xlfn.XLOOKUP($A23,Results!$A$2:$A$2256,Results!N$2:N$2256,"") -> 0 | ... BE23: =_xlfn.XLOOKUP($A23,Results!$A$2:$A$2256,Results!Z$2:Z$2256,"") -> 0
A24: 905701 | B24: 281670 | C24: NULL | D24: S4741948.001 | E24: =VLOOKUP(F24,'RPA Vendor Data '!F21:$G$2418,2) -> FROST ELECTRIC SUPPLY CO | F24: 11364 | G24: 4 | H24: Wire 12 AWG White THHN Stranded 500 Foot Reel 600 Volt Copper Wire | I24: 1000 | J24: M | K24: M | L24: 175.98 | M24: GENERIC WIRE | N24: THHN-12-STR19-WHT-CU-500S/R | O24: NULL | P24: AK10438370 | Q24: 98010022910 | R24: 175.98 | S24: 45744.501 | T24: PA_SRDC | U24: 45744.287 | V24: PAUSER | W24: NULL | X24: 4 | Y24: 201,0,0 | Z24: NULL | AA24: 175.98 | AB24: NULL | AC24: GENERIC WIRE | AD24: GENERIC WIRE | AE24: AI | AF24: - | AG24: https://www.frostelectric.com/buy/product/wire-12/12001?text=Wire+12+AWG+White+THHN+Stranded+500+Foot+Reel+600+Volt+Copper+Wire | AI24: MATERIAL | AJ24: =VLOOKUP(A24,'Classification Test Result'!$A$2:$D$2428,4,FALSE) -> #N/A | AL24: =_xlfn.XLOOKUP($A24,Results!$A$2:$A$2256,Results!G$2:G$2256,"") -> 0 | AM24: =_xlfn.XLOOKUP($A24,Results!$A$2:$A$2256,Results!H$2:H$2256,"") -> 0 | AN24: =_xlfn.XLOOKUP($A24,Results!$A$2:$A$2256,Results!I$2:I$2256,"") -> 0 | AO24: =_xlfn.XLOOKUP($A24,Results!$A$2:$A$2256,Results!J$2:J$2256,"") -> 0 | AP24: =_xlfn.XLOOKUP($A24,Results!$A$2:$A$2256,Results!K$2:K$2256,"") -> 0 | AQ24: =_xlfn.XLOOKUP($A24,Results!$A$2:$A$2256,Results!L$2:L$2256,"") -> 0 | AR24: =_xlfn.XLOOKUP($A24,Results!$A$2:$A$2256,Results!M$2:M$2256,"") -> 0 | AS24: =_xlfn.XLOOKUP($A24,Results!$A$2:$A$2256,Results!N$2:N$2256,"") -> 0 | ... BE24: =_xlfn.XLOOKUP($A24,Results!$A$2:$A$2256,Results!Z$2:Z$2256,"") -> 0
A25: 905702 | B25: 281962 | C25: NULL | D25: S4742832.001 | E25: =VLOOKUP(F25,'RPA Vendor Data '!F22:$G$2418,2) -> FROST ELECTRIC SUPPLY CO | F25: 11364 | G25: 2 | H25: Wire 12 AWG Green THHN Stranded 500 Foot Reel 600 Volt Copper Wire | I25: 500 | J25: M | K25: M | L25: 175.98 | M25: GENERIC WIRE | N25: THHN-12-STR19-GRN-CU-500S/R | O25: NULL | P25: AK10438370 | Q25: 98010022910 | R25: 87.99 | S25: 45744.876 | T25: PA_SRDC | U25: 45744.662 | V25: PAUSER | W25: NULL | X25: 0 | Y25: 201 | Z25: NULL | AA25: NULL | AB25: NULL | AC25: GENERIC WIRE | AD25: GENERIC WIRE | AE25: AI | AF25: - | AG25: https://www.frostelectric.com/buy/product/wire-12/11990?text=Wire+12+AWG+Green+THHN+Stranded+500+Foot+Reel+600+Volt+Copper+Wire | AI25: MATERIAL | AJ25: =VLOOKUP(A25,'Classification Test Result'!$A$2:$D$2428,4,FALSE) -> #N/A | AL25: =_xlfn.XLOOKUP($A25,Results!$A$2:$A$2256,Results!G$2:G$2256,"") -> 0 | AM25: =_xlfn.XLOOKUP($A25,Results!$A$2:$A$2256,Results!H$2:H$2256,"") -> 0 | AN25: =_xlfn.XLOOKUP($A25,Results!$A$2:$A$2256,Results!I$2:I$2256,"") -> 0 | AO25: =_xlfn.XLOOKUP($A25,Results!$A$2:$A$2256,Results!J$2:J$2256,"") -> 0 | AP25: =_xlfn.XLOOKUP($A25,Results!$A$2:$A$2256,Results!K$2:K$2256,"") -> 0 | AQ25: =_xlfn.XLOOKUP($A25,Results!$A$2:$A$2256,Results!L$2:L$2256,"") -> 0 | AR25: =_xlfn.XLOOKUP($A25,Results!$A$2:$A$2256,Results!M$2:M$2256,"") -> 0 | AS25: =_xlfn.XLOOKUP($A25,Results!$A$2:$A$2256,Results!N$2:N$2256,"") -> 0 | ... BE25: =_xlfn.XLOOKUP($A25,Results!$A$2:$A$2256,Results!Z$2:Z$2256,"") -> 0
A26: 905703 | B26: 281670 | C26: NULL | D26: S4741948.001 | E26: =VLOOKUP(F26,'RPA Vendor Data '!F23:$G$2418,2) -> FROST ELECTRIC SUPPLY CO | F26: 11364 | G26: 3 | H26: Wire 12 AWG Green THHN Stranded 500 Foot Reel 600 Volt Copper Wire | I26: 1000 | J26: M | K26: M | L26: 175.98 | M26: GENERIC WIRE | N26: THHN-12-STR19-GRN-CU-500S/R | O26: NULL | P26: AK10438354 | Q26: 98010022940 | R26: 175.98 | S26: 45744.501 | T26: PA_SRDC | U26: 45744.287 | V26: PAUSER | W26: NULL | X26: 3 | Y26: 201,0,0 | Z26: NULL | AA26: 175.98 | AB26: NULL | AC26: GENERIC WIRE | AD26: GENERIC WIRE | AE26: AI | AF26: - | AG26: https://www.frostelectric.com/buy/product/wire-12/11990?text=Wire+12+AWG+Green+THHN+Stranded+500+Foot+Reel+600+Volt+Copper+Wire | AI26: MATERIAL | AJ26: =VLOOKUP(A26,'Classification Test Result'!$A$2:$D$2428,4,FALSE) -> #N/A | AL26: =_xlfn.XLOOKUP($A26,Results!$A$2:$A$2256,Results!G$2:G$2256,"") -> 0 | AM26: =_xlfn.XLOOKUP($A26,Results!$A$2:$A$2256,Results!H$2:H$2256,"") -> 0 | AN26: =_xlfn.XLOOKUP($A26,Results!$A$2:$A$2256,Results!I$2:I$2256,"") -> 0 | AO26: =_xlfn.XLOOKUP($A26,Results!$A$2:$A$2256,Results!J$2:J$2256,"") -> 0 | AP26: =_xlfn.XLOOKUP($A26,Results!$A$2:$A$2256,Results!K$2:K$2256,"") -> 0 | AQ26: =_xlfn.XLOOKUP($A26,Results!$A$2:$A$2256,Results!L$2:L$2256,"") -> 0 | AR26: =_xlfn.XLOOKUP($A26,Results!$A$2:$A$2256,Results!M$2:M$2256,"") -> 0 | AS26: =_xlfn.XLOOKUP($A26,Results!$A$2:$A$2256,Results!N$2:N$2256,"") -> 0 | ... BE26: =_xlfn.XLOOKUP($A26,Results!$A$2:$A$2256,Results!Z$2:Z$2256,"") -> 0
A27: 905704 | B27: 281670 | C27: NULL | D27: S4741948.001 | E27: =VLOOKUP(F27,'RPA Vendor Data '!F24:$G$2418,2) -> FROST ELECTRIC SUPPLY CO | F27: 11364 | G27: 5 | H27: Wire 12 AWG Blue THHN Stranded 500 Foot Reel 600 Volt Copper Wire | I27: 1000 | J27: M | K27: M | L27: 175.98 | M27: GENERIC WIRE | N27: THHN-12-STR19-BLU-CU-500S/R | O27: NULL | P27: AK10438350 | Q27: 98010022930 | R27: 175.98 | S27: 45744.501 | T27: PA_SRDC | U27: 45744.287 | V27: PAUSER | W27: NULL | X27: 5 | Y27: 201,0,0 | Z27: NULL | AA27: 175.98 | AB27: NULL | AC27: GENERIC WIRE | AD27: GENERIC WIRE | AE27: AI | AF27: - | AG27: https://www.frostelectric.com/buy/product/wire-12/11986?text=Wire+12+AWG+Blue+THHN+Stranded+500+Foot+Reel+600+Volt+Copper+Wire | AI27: MATERIAL | AJ27: =VLOOKUP(A27,'Classification Test Result'!$A$2:$D$2428,4,FALSE) -> #N/A | AL27: =_xlfn.XLOOKUP($A27,Results!$A$2:$A$2256,Results!G$2:G$2256,"") -> 0 | AM27: =_xlfn.XLOOKUP($A27,Results!$A$2:$A$2256,Results!H$2:H$2256,"") -> 0 | AN27: =_xlfn.XLOOKUP($A27,Results!$A$2:$A$2256,Results!I$2:I$2256,"") -> 0 | AO27: =_xlfn.XLOOKUP($A27,Results!$A$2:$A$2256,Results!J$2:J$2256,"") -> 0 | AP27: =_xlfn.XLOOKUP($A27,Results!$A$2:$A$2256,Results!K$2:K$2256,"") -> 0 | AQ27: =_xlfn.XLOOKUP($A27,Results!$A$2:$A$2256,Results!L$2:L$2256,"") -> 0 | AR27: =_xlfn.XLOOKUP($A27,Results!$A$2:$A$2256,Results!M$2:M$2256,"") -> 0 | AS27: =_xlfn.XLOOKUP($A27,Results!$A$2:$A$2256,Results!N$2:N$2256,"") -> 0 | ... BE27: =_xlfn.XLOOKUP($A27,Results!$A$2:$A$2256,Results!Z$2:Z$2256,"") -> TRUE
A28: 905705 | B28: 281670 | C28: NULL | D28: S4741948.001 | E28: =VLOOKUP(F28,'RPA Vendor Data '!F25:$G$2418,2) -> FROST ELECTRIC SUPPLY CO | F28: 11364 | G28: 2 | H28: Wire 12 AWG Black THHN Stranded 500 Foot Reel 600 Volt Copper Wire | I28: 1000 | J28: M | K28: M | L28: 175.98 | M28: GENERIC WIRE | N28: THHN-12-STR19-BLK-CU-500S/R | O28: NULL | P28: AK10438348 | Q28: 98010022900 | R28: 175.98 | S28: 45744.501 | T28: PA_SRDC | U28: 45744.287 | V28: PAUSER | W28: NULL | X28: 2 | Y28: 201,0,0 | Z28: NULL | AA28: 175.98 | AB28: NULL | AC28: GENERIC WIRE | AD28: GENERIC WIRE | AE28: AI | AF28: - | AG28: https://www.frostelectric.com/buy/product/wire-12/11984?text=Wire+12+AWG+Black+THHN+Stranded+500+Foot+Reel+600+Volt+Copper+Wire | AI28: MATERIAL | AJ28: =VLOOKUP(A28,'Classification Test Result'!$A$2:$D$2428,4,FALSE) -> #N/A | AL28: =_xlfn.XLOOKUP($A28,Results!$A$2:$A$2256,Results!G$2:G$2256,"") -> 0 | AM28: =_xlfn.XLOOKUP($A28,Results!$A$2:$A$2256,Results!H$2:H$2256,"") -> 0 | AN28: =_xlfn.XLOOKUP($A28,Results!$A$2:$A$2256,Results!I$2:I$2256,"") -> 0 | AO28: =_xlfn.XLOOKUP($A28,Results!$A$2:$A$2256,Results!J$2:J$2256,"") -> 0 | AP28: =_xlfn.XLOOKUP($A28,Results!$A$2:$A$2256,Results!K$2:K$2256,"") -> 0 | AQ28: =_xlfn.XLOOKUP($A28,Results!$A$2:$A$2256,Results!L$2:L$2256,"") -> 0 | AR28: =_xlfn.XLOOKUP($A28,Results!$A$2:$A$2256,Results!M$2:M$2256,"") -> 0 | AS28: =_xlfn.XLOOKUP($A28,Results!$A$2:$A$2256,Results!N$2:N$2256,"") -> 0 | ... BE28: =_xlfn.XLOOKUP($A28,Results!$A$2:$A$2256,Results!Z$2:Z$2256,"") -> 0
A29: 905706 | B29: 281986 | C29: NULL | D29: S4743676.001 | E29: =VLOOKUP(F29,'RPA Vendor Data '!F26:$G$2418,2) -> FROST ELECTRIC SUPPLY CO | F29: 11364 | G29: 4 | H29: Wire 10 AWG Green THHN Stranded 500 Foot Reel 600 Volt Copper Wire | I29: 500 | J29: M | K29: M | L29: 295.52 | M29: GENERIC WIRE | N29: THHN-10-STR19-GRN-CU-500S/R | O29: NULL | P29: AK10438157 | Q29: 98010023040 | R29: 147.76 | S29: 45744.897 | T29: PA_SRDC | U29: 45744.667 | V29: PAUSER | W29: NULL | X29: 0 | Y29: 201,0,0 | Z29: NULL | AA29: 295.52 | AB29: NULL | AC29: GENERIC WIRE | AD29: GENERIC WIRE | AE29: AI | AF29: - | AG29: https://www.frostelectric.com/buy/product/wire-10/11950?text=Wire+10+AWG+Green+THHN+Stranded+500+Foot+Reel+600+Volt+Copper+Wire | AI29: MATERIAL | AJ29: =VLOOKUP(A29,'Classification Test Result'!$A$2:$D$2428,4,FALSE) -> #N/A | AL29: =_xlfn.XLOOKUP($A29,Results!$A$2:$A$2256,Results!G$2:G$2256,"") -> 0 | AM29: =_xlfn.XLOOKUP($A29,Results!$A$2:$A$2256,Results!H$2:H$2256,"") -> 0 | AN29: =_xlfn.XLOOKUP($A29,Results!$A$2:$A$2256,Results!I$2:I$2256,"") -> 0 | AO29: =_xlfn.XLOOKUP($A29,Results!$A$2:$A$2256,Results!J$2:J$2256,"") -> 0 | AP29: =_xlfn.XLOOKUP($A29,Results!$A$2:$A$2256,Results!K$2:K$2256,"") -> 0 | AQ29: =_xlfn.XLOOKUP($A29,Results!$A$2:$A$2256,Results!L$2:L$2256,"") -> 0 | AR29: =_xlfn.XLOOKUP($A29,Results!$A$2:$A$2256,Results!M$2:M$2256,"") -> 0 | AS29: =_xlfn.XLOOKUP($A29,Results!$A$2:$A$2256,Results!N$2:N$2256,"") -> 0 | ... BE29: =_xlfn.XLOOKUP($A29,Results!$A$2:$A$2256,Results!Z$2:Z$2256,"") -> 0
A30: 905707 | B30: 281967 | C30: NULL | D30: S4743296.001 | E30: =VLOOKUP(F30,'RPA Vendor Data '!F27:$G$2418,2) -> FROST ELECTRIC SUPPLY CO | F30: 11364 | G30: 3 | H30: Wire 10 AWG Green THHN Stranded 500 Foot Reel 600 Volt Copper Wire | I30: 500 | J30: M | K30: M | L30: 295.52 | M30: GENERIC WIRE | N30: THHN-10-STR19-GRN-CU-500S/R | O30: NULL | P30: AK10438157 | Q30: 98010023040 | R30: 147.76 | S30: 45744.876 | T30: PA_SRDC | U30: 45744.662 | V30: PAUSER | W30: NULL | X30: 0 | Y30: 201 | Z30: NULL | AA30: NULL | AB30: NULL | AC30: GENERIC WIRE | AD30: GENERIC WIRE | AE30: AI | AF30: - | AG30: https://www.frostelectric.com/buy/product/wire-10/11950?text=Wire+10+AWG+Green+THHN+Stranded+500+Foot+Reel+600+Volt+Copper+Wire | AI30: MATERIAL | AJ30: =VLOOKUP(A30,'Classification Test Result'!$A$2:$D$2428,4,FALSE) -> #N/A | AL30: =_xlfn.XLOOKUP($A30,Results!$A$2:$A$2256,Results!G$2:G$2256,"") -> 0 | AM30: =_xlfn.XLOOKUP($A30,Results!$A$2:$A$2256,Results!H$2:H$2256,"") -> 0 | AN30: =_xlfn.XLOOKUP($A30,Results!$A$2:$A$2256,Results!I$2:I$2256,"") -> 0 | AO30: =_xlfn.XLOOKUP($A30,Results!$A$2:$A$2256,Results!J$2:J$2256,"") -> 0 | AP30: =_xlfn.XLOOKUP($A30,Results!$A$2:$A$2256,Results!K$2:K$2256,"") -> 0 | AQ30: =_xlfn.XLOOKUP($A30,Results!$A$2:$A$2256,Results!L$2:L$2256,"") -> 0 | AR30: =_xlfn.XLOOKUP($A30,Results!$A$2:$A$2256,Results!M$2:M$2256,"") -> 0 | AS30: =_xlfn.XLOOKUP($A30,Results!$A$2:$A$2256,Results!N$2:N$2256,"") -> 0 | ... BE30: =_xlfn.XLOOKUP($A30,Results!$A$2:$A$2256,Results!Z$2:Z$2256,"") -> 0
A31: 905708 | B31: 281966 | C31: NULL | D31: S4743353.001 | E31: =VLOOKUP(F31,'RPA Vendor Data '!F28:$G$2418,2) -> FROST ELECTRIC SUPPLY CO | F31: 11364 | G31: 2 | H31: Wire 10 AWG Blue THHN Stranded 500 Foot Reel 600 Volt Copper Wire | I31: 500 | J31: M | K31: M | L31: 295.52 | M31: GENERIC WIRE | N31: THHN-10-STR19-BLU-CU-500S/R | O31: NULL | P31: AK10438148 | Q31: 98010023030 | R31: 147.76 | S31: 45744.876 | T31: PA_SRDC | U31: 45744.662 | V31: PAUSER | W31: NULL | X31: 2 | Y31: 201,0,0 | Z31: NULL | AA31: 295.52 | AB31: NULL | AC31: GENERIC WIRE | AD31: GENERIC WIRE | AE31: AI | AF31: - | AG31: https://www.frostelectric.com/buy/product/wire-10/11946?text=Wire+10+AWG+Blue+THHN+Stranded+500+Foot+Reel+600+Volt+Copper+Wire | AI31: MATERIAL | AJ31: =VLOOKUP(A31,'Classification Test Result'!$A$2:$D$2428,4,FALSE) -> #N/A | AL31: =_xlfn.XLOOKUP($A31,Results!$A$2:$A$2256,Results!G$2:G$2256,"") -> 0 | AM31: =_xlfn.XLOOKUP($A31,Results!$A$2:$A$2256,Results!H$2:H$2256,"") -> 0 | AN31: =_xlfn.XLOOKUP($A31,Results!$A$2:$A$2256,Results!I$2:I$2256,"") -> 0 | AO31: =_xlfn.XLOOKUP($A31,Results!$A$2:$A$2256,Results!J$2:J$2256,"") -> 0 | AP31: =_xlfn.XLOOKUP($A31,Results!$A$2:$A$2256,Results!K$2:K$2256,"") -> 0 | AQ31: =_xlfn.XLOOKUP($A31,Results!$A$2:$A$2256,Results!L$2:L$2256,"") -> 0 | AR31: =_xlfn.XLOOKUP($A31,Results!$A$2:$A$2256,Results!M$2:M$2256,"") -> 0 | AS31: =_xlfn.XLOOKUP($A31,Results!$A$2:$A$2256,Results!N$2:N$2256,"") -> 0 | ... BE31: =_xlfn.XLOOKUP($A31,Results!$A$2:$A$2256,Results!Z$2:Z$2256,"") -> 0
A32: 905709 | B32: 281428 | C32: NULL | D32: S142052017.001 | E32: =VLOOKUP(F32,'RPA Vendor Data '!F29:$G$2418,2) -> REXEL USA, INC. | F32: 12873 | G32: 1 | H32: WIR FPBTCBK 234591 FLOORPORT FLANGED BLANK TOP BK | I32: 1 | J32: EA | K32: E | L32: 119.098 | M32: WIREMOLD | N32: FPBTCBK | O32: 234591 | P32: AK10565407 | Q32: 78677615201 | R32: 119.1 | S32: 45744.292 | T32: PA_SRDC | U32: 45744.063 | V32: PAUSER | W32: NULL | X32: 1 | Y32: 0,0,0 | Z32: 119.098 | AA32: 119.098 | AB32: 195 | AC32: WIREMOLD | AD32: WIREMOLD | AE32: AI | AF32: - | AG32: https://www.rexelusa.com/p/234591/wiremold/blank-flanged-cover-assembly-black-die-cast-aluminum/786776152012/fpbtcbk | AI32: MATERIAL | AJ32: =VLOOKUP(A32,'Classification Test Result'!$A$2:$D$2428,4,FALSE) -> #N/A | AL32: =_xlfn.XLOOKUP($A32,Results!$A$2:$A$2256,Results!G$2:G$2256,"") -> 0 | AM32: =_xlfn.XLOOKUP($A32,Results!$A$2:$A$2256,Results!H$2:H$2256,"") -> 0 | AN32: =_xlfn.XLOOKUP($A32,Results!$A$2:$A$2256,Results!I$2:I$2256,"") -> 0 | AO32: =_xlfn.XLOOKUP($A32,Results!$A$2:$A$2256,Results!J$2:J$2256,"") -> 0 | AP32: =_xlfn.XLOOKUP($A32,Results!$A$2:$A$2256,Results!K$2:K$2256,"") -> 0 | AQ32: =_xlfn.XLOOKUP($A32,Results!$A$2:$A$2256,Results!L$2:L$2256,"") -> 0 | AR32: =_xlfn.XLOOKUP($A32,Results!$A$2:$A$2256,Results!M$2:M$2256,"") -> 0 | AS32: =_xlfn.XLOOKUP($A32,Results!$A$2:$A$2256,Results!N$2:N$2256,"") -> 0 | ... BE32: =_xlfn.XLOOKUP($A32,Results!$A$2:$A$2256,Results!Z$2:Z$2256,"") -> 0
A33: 905710 | B33: 281742 | C33: NULL | D33: 7701018 | F33: 10567 | G33: 3 | H33: WINTER SERVICE CHARGE | I33: 4 | J33: Yard | K33: E | L33: 12 | M33: NULL | N33: NULL | O33: NULL | P33: NULL | Q33: NULL | R33: 54 | S33: 45744.543 | T33: PA_SRDC | U33: 45744.321 | V33: PAUSER | W33: NULL | X33: 0 | Y33: 999 | Z33: NULL | AA33: NULL | AB33: NULL | AC33: FEE | AD33: FEE | AE33: AI | AI33: =IF(COUNTIF(Classification!$A$2:$A$338, H33)>0,"FEE", " ") -> FEE | AJ33: =VLOOKUP(A33,'Classification Test Result'!$A$2:$D$2428,4,FALSE) -> #N/A | AL33: =_xlfn.XLOOKUP($A33,Results!$A$2:$A$2256,Results!G$2:G$2256,"") -> 0 | AM33: =_xlfn.XLOOKUP($A33,Results!$A$2:$A$2256,Results!H$2:H$2256,"") -> 0 | AN33: =_xlfn.XLOOKUP($A33,Results!$A$2:$A$2256,Results!I$2:I$2256,"") -> 0 | AO33: =_xlfn.XLOOKUP($A33,Results!$A$2:$A$2256,Results!J$2:J$2256,"") -> 0 | AP33: =_xlfn.XLOOKUP($A33,Results!$A$2:$A$2256,Results!K$2:K$2256,"") -> 0 | AQ33: =_xlfn.XLOOKUP($A33,Results!$A$2:$A$2256,Results!L$2:L$2256,"") -> 0 | AR33: =_xlfn.XLOOKUP($A33,Results!$A$2:$A$2256,Results!M$2:M$2256,"") -> 0 | AS33: =_xlfn.XLOOKUP($A33,Results!$A$2:$A$2256,Results!N$2:N$2256,"") -> 0 | ... BE33: =_xlfn.XLOOKUP($A33,Results!$A$2:$A$2256,Results!Z$2:Z$2256,"") -> 0
A34: 905711 | B34: 281887 | C34: NULL | D34: 15586 | F34: 10441 | G34: 14 | H34: WINTER SERVICE | I34: 10 | J34: YQ/ + YDC | K34: E | L34: 6 | M34: NULL | N34: NULL | O34: NULL | P34: NULL | Q34: NULL | R34: 60 | S34: 45744.668 | T34: PA_SRDC | U34: 45744.449 | V34: PAUSER | W34: NULL | X34: 0 | Y34: 999 | Z34: NULL | AA34: NULL | AB34: NULL | AC34: UNDEFINED | AD34: UNDEFINED | AE34: AI | AI34: FEE | AJ34: =VLOOKUP(A34,'Classification Test Result'!$A$2:$D$2428,4,FALSE) -> #N/A | AL34: =_xlfn.XLOOKUP($A34,Results!$A$2:$A$2256,Results!G$2:G$2256,"") -> 0 | AM34: =_xlfn.XLOOKUP($A34,Results!$A$2:$A$2256,Results!H$2:H$2256,"") -> 0 | AN34: =_xlfn.XLOOKUP($A34,Results!$A$2:$A$2256,Results!I$2:I$2256,"") -> 0 | AO34: =_xlfn.XLOOKUP($A34,Results!$A$2:$A$2256,Results!J$2:J$2256,"") -> 0 | AP34: =_xlfn.XLOOKUP($A34,Results!$A$2:$A$2256,Results!K$2:K$2256,"") -> 0 | AQ34: =_xlfn.XLOOKUP($A34,Results!$A$2:$A$2256,Results!L$2:L$2256,"") -> 0 | AR34: =_xlfn.XLOOKUP($A34,Results!$A$2:$A$2256,Results!M$2:M$2256,"") -> 0 | AS34: =_xlfn.XLOOKUP($A34,Results!$A$2:$A$2256,Results!N$2:N$2256,"") -> 0 | ... BE34: =_xlfn.XLOOKUP($A34,Results!$A$2:$A$2256,Results!Z$2:Z$2256,"") -> 0
A35: 905712 | B35: 281887 | C35: NULL | D35: 15586 | F35: 10441 | G35: 2 | H35: WINTER SERVICE | I35: 10 | J35: YQ/ + YDC | K35: E | L35: 6 | M35: NULL | N35: NULL | O35: NULL | P35: NULL | Q35: NULL | R35: 60 | S35: 45744.668 | T35: PA_SRDC | U35: 45744.449 | V35: PAUSER | W35: NULL | X35: 0 | Y35: 999 | Z35: NULL | AA35: NULL | AB35: NULL | AC35: UNDEFINED | AD35: UNDEFINED | AE35: AI | AI35: FEE | AJ35: =VLOOKUP(A35,'Classification Test Result'!$A$2:$D$2428,4,FALSE) -> #N/A | AL35: =_xlfn.XLOOKUP($A35,Results!$A$2:$A$2256,Results!G$2:G$2256,"") -> 0 | AM35: =_xlfn.XLOOKUP($A35,Results!$A$2:$A$2256,Results!H$2:H$2256,"") -> 0 | AN35: =_xlfn.XLOOKUP($A35,Results!$A$2:$A$2256,Results!I$2:I$2256,"") -> 0 | AO35: =_xlfn.XLOOKUP($A35,Results!$A$2:$A$2256,Results!J$2:J$2256,"") -> 0 | AP35: =_xlfn.XLOOKUP($A35,Results!$A$2:$A$2256,Results!K$2:K$2256,"") -> 0 | AQ35: =_xlfn.XLOOKUP($A35,Results!$A$2:$A$2256,Results!L$2:L$2256,"") -> 0 | AR35: =_xlfn.XLOOKUP($A35,Results!$A$2:$A$2256,Results!M$2:M$2256,"") -> 0 | AS35: =_xlfn.XLOOKUP($A35,Results!$A$2:$A$2256,Results!N$2:N$2256,"") -> 0 | ... BE35: =_xlfn.XLOOKUP($A35,Results!$A$2:$A$2256,Results!Z$2:Z$2256,"") -> 0
A36: 905713 | B36: 281887 | C36: NULL | D36: 15586 | F36: 10441 | G36: 18 | H36: WINTER SERVICE | I36: 10 | J36: YQ/ + YDC | K36: E | L36: 6 | M36: NULL | N36: NULL | O36: NULL | P36: NULL | Q36: NULL | R36: 60 | S36: 45744.668 | T36: PA_SRDC | U36: 45744.449 | V36: PAUSER | W36: NULL | X36: 0 | Y36: 999 | Z36: NULL | AA36: NULL | AB36: NULL | AC36: UNDEFINED | AD36: UNDEFINED | AE36: AI | AI36: FEE | AJ36: =VLOOKUP(A36,'Classification Test Result'!$A$2:$D$2428,4,FALSE) -> #N/A | AL36: =_xlfn.XLOOKUP($A36,Results!$A$2:$A$2256,Results!G$2:G$2256,"") -> 0 | AM36: =_xlfn.XLOOKUP($A36,Results!$A$2:$A$2256,Results!H$2:H$2256,"") -> 0 | AN36: =_xlfn.XLOOKUP($A36,Results!$A$2:$A$2256,Results!I$2:I$2256,"") -> 0 | AO36: =_xlfn.XLOOKUP($A36,Results!$A$2:$A$2256,Results!J$2:J$2256,"") -> 0 | AP36: =_xlfn.XLOOKUP($A36,Results!$A$2:$A$2256,Results!K$2:K$2256,"") -> 0 | AQ36: =_xlfn.XLOOKUP($A36,Results!$A$2:$A$2256,Results!L$2:L$2256,"") -> 0 | AR36: =_xlfn.XLOOKUP($A36,Results!$A$2:$A$2256,Results!M$2:M$2256,"") -> 0 | AS36: =_xlfn.XLOOKUP($A36,Results!$A$2:$A$2256,Results!N$2:N$2256,"") -> 0 | ... BE36: =_xlfn.XLOOKUP($A36,Results!$A$2:$A$2256,Results!Z$2:Z$2256,"") -> 0
A37: 905714 | B37: 281887 | C37: NULL | D37: 15586 | F37: 10441 | G37: 10 | H37: WINTER SERVICE | I37: 10 | J37: YQ/ + YDC | K37: E | L37: 6 | M37: NULL | N37: NULL | O37: NULL | P37: NULL | Q37: NULL | R37: 60 | S37: 45744.668 | T37: PA_SRDC | U37: 45744.449 | V37: PAUSER | W37: NULL | X37: 0 | Y37: 999 | Z37: NULL | AA37: NULL | AB37: NULL | AC37: UNDEFINED | AD37: UNDEFINED | AE37: AI | AI37: FEE | AJ37: =VLOOKUP(A37,'Classification Test Result'!$A$2:$D$2428,4,FALSE) -> #N/A | AL37: =_xlfn.XLOOKUP($A37,Results!$A$2:$A$2256,Results!G$2:G$2256,"") -> 0 | AM37: =_xlfn.XLOOKUP($A37,Results!$A$2:$A$2256,Results!H$2:H$2256,"") -> 0 | AN37: =_xlfn.XLOOKUP($A37,Results!$A$2:$A$2256,Results!I$2:I$2256,"") -> 0 | AO37: =_xlfn.XLOOKUP($A37,Results!$A$2:$A$2256,Results!J$2:J$2256,"") -> 0 | AP37: =_xlfn.XLOOKUP($A37,Results!$A$2:$A$2256,Results!K$2:K$2256,"") -> 0 | AQ37: =_xlfn.XLOOKUP($A37,Results!$A$2:$A$2256,Results!L$2:L$2256,"") -> 0 | AR37: =_xlfn.XLOOKUP($A37,Results!$A$2:$A$2256,Results!M$2:M$2256,"") -> 0 | AS37: =_xlfn.XLOOKUP($A37,Results!$A$2:$A$2256,Results!N$2:N$2256,"") -> 0 | ... BE37: =_xlfn.XLOOKUP($A37,Results!$A$2:$A$2256,Results!Z$2:Z$2256,"") -> 0
A38: 905715 | B38: 281887 | C38: NULL | D38: 15586 | F38: 10441 | G38: 6 | H38: WINTER SERVICE | I38: 10 | J38: YQ/ + YDC | K38: E | L38: 6 | M38: NULL | N38: NULL | O38: NULL | P38: NULL | Q38: NULL | R38: 60 | S38: 45744.668 | T38: PA_SRDC | U38: 45744.449 | V38: PAUSER | W38: NULL | X38: 0 | Y38: 999 | Z38: NULL | AA38: NULL | AB38: NULL | AC38: UNDEFINED | AD38: UNDEFINED | AE38: AI | AI38: FEE | AJ38: =VLOOKUP(A38,'Classification Test Result'!$A$2:$D$2428,4,FALSE) -> #N/A | AL38: =_xlfn.XLOOKUP($A38,Results!$A$2:$A$2256,Results!G$2:G$2256,"") -> 0 | AM38: =_xlfn.XLOOKUP($A38,Results!$A$2:$A$2256,Results!H$2:H$2256,"") -> 0 | AN38: =_xlfn.XLOOKUP($A38,Results!$A$2:$A$2256,Results!I$2:I$2256,"") -> 0 | AO38: =_xlfn.XLOOKUP($A38,Results!$A$2:$A$2256,Results!J$2:J$2256,"") -> 0 | AP38: =_xlfn.XLOOKUP($A38,Results!$A$2:$A$2256,Results!K$2:K$2256,"") -> 0 | AQ38: =_xlfn.XLOOKUP($A38,Results!$A$2:$A$2256,Results!L$2:L$2256,"") -> 0 | AR38: =_xlfn.XLOOKUP($A38,Results!$A$2:$A$2256,Results!M$2:M$2256,"") -> 0 | AS38: =_xlfn.XLOOKUP($A38,Results!$A$2:$A$2256,Results!N$2:N$2256,"") -> 0 | ... BE38: =_xlfn.XLOOKUP($A38,Results!$A$2:$A$2256,Results!Z$2:Z$2256,"") -> 0
A39: 905716 | B39: 281963 | C39: NULL | D39: S4742551.002 | E39: =VLOOKUP(F39,'RPA Vendor Data '!F30:$G$2418,2) -> FROST ELECTRIC SUPPLY CO | F39: 11364 | G39: 1 | H39: WIEGMANN SCF1010 FLUSH SCREW COVER ONLY PAINTED N1 | I39: 1 | J39: EA | K39: E | L39: 28.39 | M39: WIEGMANN | N39: SCF1010 | O39: NULL | P39: NULL | Q39: 78672531352 | R39: 28.39 | S39: 45744.876 | T39: PA_SRDC | U39: 45744.662 | V39: PAUSER | W39: NULL | X39: 0 | Y39: 201 | Z39: NULL | AA39: NULL | AB39: NULL | AC39: WIEGMANN | AD39: WIEGMANN | AE39: AI | AF39: 39121324 | AG39: https://www.gordonelectricsupply.com/p/Wiegmann-Scf1010-Nm1-Flush-Cover-F-Sc-Bx/5598417?srsltid=AfmBOopMbRU8j_p2qB4ADUlZKRPJIelbFkNwfj0nAwlofMtU0rnNdVtk | AI39: MATERIAL | AJ39: =VLOOKUP(A39,'Classification Test Result'!$A$2:$D$2428,4,FALSE) -> #N/A | AL39: =_xlfn.XLOOKUP($A39,Results!$A$2:$A$2256,Results!G$2:G$2256,"") -> 1112794 | AM39: =_xlfn.XLOOKUP($A39,Results!$A$2:$A$2256,Results!H$2:H$2256,"") -> SCF1010 | AN39: =_xlfn.XLOOKUP($A39,Results!$A$2:$A$2256,Results!I$2:I$2256,"") -> WIEGMANN | AO39: =_xlfn.XLOOKUP($A39,Results!$A$2:$A$2256,Results!J$2:J$2256,"") -> 786725313525 | AP39: =_xlfn.XLOOKUP($A39,Results!$A$2:$A$2256,Results!K$2:K$2256,"") -> 39121302 | AQ39: =_xlfn.XLOOKUP($A39,Results!$A$2:$A$2256,Results!L$2:L$2256,"") -> 0 | AR39: =_xlfn.XLOOKUP($A39,Results!$A$2:$A$2256,Results!M$2:M$2256,"") -> 101789 | AS39: =_xlfn.XLOOKUP($A39,Results!$A$2:$A$2256,Results!N$2:N$2256,"") -> WIEG SCF1010 NM1 FLUSH CVR F/SC BX | ... BE39: =_xlfn.XLOOKUP($A39,Results!$A$2:$A$2256,Results!Z$2:Z$2256,"") -> TRUE
A40: 905717 | B40: 281318 | C40: NULL | D40: S009000673.002 | E40: =VLOOKUP(F40,'RPA Vendor Data '!F31:$G$2418,2) -> VIKING ELECTRIC | F40: 13536 | G40: 4 | H40: WIEG SC121204NK SCPB 12X12X4 NO KO | I40: 1 | J40: EA | K40: E | L40: 33.76 | M40: WIEGMANN | N40: SC121204NK | O40: NULL | P40: AK10519466 | Q40: NULL | R40: 33.76 | S40: 45744.189 | T40: PA_SRDC | U40: 45743.967 | V40: PAUSER | W40: NULL | X40: 5 | Y40: 0,0,0 | Z40: 33.76 | AA40: 33.76 | AB40: 136 | AC40: WIEGMANN | AD40: WIEGMANN | AE40: AI | AF40: 39121324 | AG40: https://www.gordonelectricsupply.com/p/Wiegmann-Sc121204Nk-Nema1-Screw-Cover-Box-No-Ko/5597206?srsltid=AfmBOoqo76wvggJp1fnuGjEo0zcawRubQuW4LDgIpJrMUGxLPT1JgIwW | AI40: MATERIAL | AJ40: =VLOOKUP(A40,'Classification Test Result'!$A$2:$D$2428,4,FALSE) -> #N/A | AL40: =_xlfn.XLOOKUP($A40,Results!$A$2:$A$2256,Results!G$2:G$2256,"") -> 341754 | AM40: =_xlfn.XLOOKUP($A40,Results!$A$2:$A$2256,Results!H$2:H$2256,"") -> SC121204NK | AN40: =_xlfn.XLOOKUP($A40,Results!$A$2:$A$2256,Results!I$2:I$2256,"") -> WIEGMANN | AO40: =_xlfn.XLOOKUP($A40,Results!$A$2:$A$2256,Results!J$2:J$2256,"") -> 786725313914 | AP40: =_xlfn.XLOOKUP($A40,Results!$A$2:$A$2256,Results!K$2:K$2256,"") -> 39121332 | AQ40: =_xlfn.XLOOKUP($A40,Results!$A$2:$A$2256,Results!L$2:L$2256,"") -> AK10519466 | AR40: =_xlfn.XLOOKUP($A40,Results!$A$2:$A$2256,Results!M$2:M$2256,"") -> 387559 | AS40: =_xlfn.XLOOKUP($A40,Results!$A$2:$A$2256,Results!N$2:N$2256,"") -> WIEG SC121204NK NEMA1 SC BOX-NO KO | ... BE40: =_xlfn.XLOOKUP($A40,Results!$A$2:$A$2256,Results!Z$2:Z$2256,"") -> TRUE
...

Sheet Results
A1: IVCE_DTL_UID | B1: ITM_LDSC | C1: MFR_NM | D1: MFR_PRT_NUM | E1: AKS_PRT_NUM | F1: UPC_CD | G1: ItemID | H1: MfrPartNum | I1: MfrName | J1: UPC | K1: UNSPSC | L1: AKPartNum | M1: DescriptionID | N1: ItemDescription | O1: CleanName | P1: UncleanName | Q1: MfrNameMatchType | R1: DescriptionSimilarity | S1: PartNumberConfidenceScore | T1: ManufacturerNameConfidenceScore | U1: UNSPSCConfidenceScore | V1: Semantic_MfrName | W1: Semantic_MfrNameConfidenceScore | X1: Semantic_UNSPSC | Y1: Semantic_UNSPSCConfidenceScore | Z1: Semantic_IsMfrClean
A2: 905679 | B2: YALE GP050VX 5,000# WAREHOUSE FORKLIFT | C2: YALE | D2: GP050VX
A3: 905680 | B3: X7 COOPER CROUSE-HINDS DIVISION CHICO CHICO X FIBER 1 LB AK10289128 | C3: CROUSE-HINDS | D3: CHICO X7 | E3: AK10289128 | O3: CROUSE HINDS | P3: COOPER CROUSE-HINDS DIVISION | Q3: SINGLE_MATCH | T3: 100
A4: 905681 | B4: X CLOSE GENERIC VENDOR-TUBPA 3/4 3/4 X CLOSE-GALVANIZED CONDUIT NIPPLE | C4: GENERIC CONDUIT/CONDUIT FITTINGS | D4: 3/4 X CLOSE | E4: AK10432182 | O4: GENERIC CONDUIT/CONDUIT FITTINGS | P4: GENERIC VENDOR-TUBPA | Q4: SINGLE_MATCH | T4: 100 | V4: SOUTHWIRE | W4: 78 | X4: 39131718 | Y4: 78 | Z4: TRUE
A5: 905682 | B5: WS LMRC-211 770734 DIGITAL V.2 SGLE RELAY RM CONTROLLER ON/OFF 0-10V DIMM | C5: WATTSTOPPER | D5: LMRC-211 | G5: 735909 | H5: LMRC211 | I5: WATTSTOPPER | J5: 754182929030 | K5: 45111808 | M5: 480852 | N5: WATT LMRC-211 ROOM CTRLR | O5: WATTSTOPPER | Q5: NO_MANUFACTURERS_FOUND | R5: 0.7024660648886563 | S5: 100 | T5: 100 | U5: 96 | V5: WATTSTOPPER | W5: 62 | Z5: TRUE
A6: 905683 | B6: WRMLD LOT 729287 * Item not returnable without RGA * (4) WD10W350-60 (8) CP10-S30 (8) WD10W350-ECS | C6: WIREMOLD | D6: LOT
A7: 905684 | B7: Wright 311 10PC Hex Bit Socket Set with 3/8 Drive Sizes 1/8 5/32 3/16 7/32 1/4 5/16 & 3/8, and 1/2 Drive Sizes 1/2 9/16 5/8 On Rail w/ 10 Clips | C7: WRIGHT TOOL | D7: 311 | F7: 76799003119 | O7: WRIGHT TOOL | P7: WRIGHT | Q7: SINGLE_MATCH | T7: 90 | X7: 27110000 | Y7: 78
A8: 905685 | B8: WIREMOLD CO SGC2-RT SINGLE GANG COMM PLATE ORTRONICS | C8: WIREMOLD | D8: SGC2-RT | O8: WIREMOLD | P8: WIREMOLD CO | Q8: MULTIPLE_MATCHES_ONE_VALID | T8: 50 | V8: ORBIT INDUSTRIES | W8: 77 | X8: 39120000 | Y8: 77 | Z8: TRUE
A9: 905686 | B9: WIREMOLD CO SGC2-ACT SINGLE GANG COMM PLT ACTIVATE | C9: WIREMOLD | D9: SGC2-ACT | O9: WIREMOLD | P9: WIREMOLD CO | Q9: SINGLE_MATCH | T9: 100
A10: 905687 | B10: WIREMOLD CO NP800C-10-2B NP800 ANOD POLE 10FT.2IN.L WBOX END | C10: WIREMOLD | D10: NP800C-10-2B | O10: WIREMOLD | P10: WIREMOLD CO | Q10: SINGLE_MATCH | T10: 100
A11: 905688 | B11: WS (Winter Service Charge - Nov 1 - Mar 31)
A12: 905689 | B12: WS (Winter Service Charge - Nov 1 - Mar 31)
A13: 905690 | B13: WS (Winter Service Charge - Nov 1 - Mar 31)
A14: 905691 | B14: WIRE-LINE 12550 1/2 STAPLE 500/BAG | C14: WIRE-LINE | D14: 12550 | F14: 60550512550 | O14: GENERIC WIRE | P14: WIRE | Q14: SINGLE_MATCH | T14: 75 | X14: 39121700 | Y14: 63
A15: 905692 | B15: WIRE-LINE 12550 1/2 STAPLE 500/BAG | C15: WIRE-LINE | D15: 12550 | F15: 60550512550 | O15: GENERIC WIRE | P15: WIRE | Q15: SINGLE_MATCH | T15: 75 | X15: 39121700 | Y15: 63
A16: 905693 | B16: WIRE-LINE 12550 1/2 STAPLE 500/BAG | C16: WIRE-LINE | D16: 12550 | F16: 60550512550 | O16: GENERIC WIRE | P16: WIRE | Q16: SINGLE_MATCH | T16: 75 | X16: 39121700 | Y16: 63
